{"error": null, "issues": [{"address": 2767, "debug": "", "description": "This contract executes a message call to to another contract. Make sure that the called contract is trusted and does not execute user-supplied code.", "filename": "/unique_chucks/23/0xff4b417892f3ca1678a288cc6296a7094bf98f0b.sol", "function": "releaseTokenOwnership()", "lineno": 525, "title": "Message call to external contract", "type": "Informational"}, {"address": 4518, "code": "ntract ERC20In", "debug": "The exception is triggered under the following conditions:\n\nstorage_3: 0x17ffffffffffffffffffffffffffffffffffffffffffbffffffffffe\ncallvalue: 0x800000001\nstorage_6: 0x9fffeffffffffffffffbffffffffff00000000000000000000003eef40000000\ncaller: 0xffffffffffffffffffffffffffffffffffffffff\ncalldatasize_ZitKOINCrowdsale: 0x3\n", "description": "A reachable exception (opcode 0xfe) has been detected. This can be caused by type errors, division by zero, out-of-bounds array access, or assert violations. This is acceptable in most situations. Note however that `assert()` should only be used to check invariants. Use `require()` for regular input checking. ", "filename": "/unique_chucks/23/0xff4b417892f3ca1678a288cc6296a7094bf98f0b.sol", "function": "fallback", "lineno": 94, "title": "Exception state", "type": "Informational"}], "success": true}